Workbook

Sheet Cover
A1: AbbVie Inc. (NYSE: ABBV) — IMCP Equity Research Model
A2: UWM Lubar School of Business — Investment Management Certificate Program
A3: Hybrid model: IMCP invested-capital framework + sell-side DCF valuation suite
A4: Analyst: [name] | June 2026
A6: WHAT THIS MODEL CONTAINS
A7: • Fin-Summary, Fin-Forecast, Fin-Capital, Fin-Ratios, Fin-FCF: IMCP invested-capital statements
A8: • Bear / Base / Bull scenarios shown as parallel columns across all IMCP tabs
A9: • Invested capital framework: NOWC + NFA = IC, asset-turnover-driven forecasts
A10: • ROIC decomposition (3 methods), 5-stage and 3-stage ROE, sustainable growth rate
A11: • FCFF and FCFE computed two ways (ex cash/debt and with cash/debt)
A12: • Drivers tab: sell-side scenario toggle and WACC build-up
A13: • DCF-FCFF and DCF-FCFE with 7-year explicit forecast + terminal value
... A17: KEY ANCHORS (FY2025A)
A18: Current share price | B18: $224.77
A19: Diluted shares (mm) | B19: 1,773
A20: Sales | B20: $61,160mm
A21: EBIT / EBIT margin | B21: $20,913mm / 34.2%
A22: Net income (GAAP) | B22: $4,186mm
A23: Net debt | B23: $63,122mm
A24: Invested capital (ex cash) | B24: ~$117,550mm
A25: WACC | B25: 7.6%
A26: Cost of equity | B26: 8.1%
A28: SOURCES & NOTES
A29: – ABBV 10-K FY2025 and FactSet Fundamentals export
A30: – GAAP net income is depressed by acquired IPR&D and Allergan intangible amortization;
A31: forward tax rate normalized to 15% (AbbVie recurring effective rate)
A32: – NFA carries ~$110B Allergan goodwill/intangibles; tangible book value is negative
A33: – Peer multiples and beta: user-supplied / FactSet consensus
A35: Color key: blue = input, black = formula, green = cross-tab link, gray = memo. Not investment advice.

Sheet Dashboard
A1: AbbVie Inc. (NYSE: ABBV) — Valuation Dashboard
A2: All methods live. Change Drivers!D6 scenario or any blue input and this updates.
A4: KEY OUTPUTS
A5: =Drivers!D7 -> BASE
A6: =Drivers!D8 -> 224.77
A7: Blended fair value ($) | B7: =AVERAGE('DCF-FCFF'!B31,'DCF-FCFE'!B28,'EVA-Residual'!B29,'EVA-Residual'!B44,Comps!C15) -> 159.99441
A8: Upside / (downside) | B8: =B7/Drivers!D8-1 -> -0.28818611
A10: VALUATION BY METHOD
A11: Method | B11: Per share | C11: Upside
A12: DCF — FCFF (firm) | B12: ='DCF-FCFF'!B31 -> 147.581 | C12: =B12/Drivers!D8-1 -> -0.34341327
A13: DCF — FCFE (equity) | B13: ='DCF-FCFE'!B28 -> 127.58623 | C13: =B13/Drivers!D8-1 -> -0.43236983
A14: EVA / MVA | B14: ='EVA-Residual'!B29 -> 159.2782 | C14: =B14/Drivers!D8-1 -> -0.29137253
A15: Residual income | B15: ='EVA-Residual'!B44 -> 193.41502 | C15: =B15/Drivers!D8-1 -> -0.13949805
A16: Trading comps (mid) | B16: =Comps!C15 -> 172.11159 | C16: =B16/Drivers!D8-1 -> -0.23427687
A17: Monte Carlo (median) | B17: 200.3 | C17: =B17/Drivers!D8-1 -> -0.10886684
A18: Blended fair value | B18: =B7 -> 159.99441 | C18: =B18/Drivers!D8-1 -> -0.28818611
A19: Current price | B19: =Drivers!D8 -> 224.77

Sheet Drivers
A1: AbbVie Inc. (ABBV) — Driver & Assumption Engine
A2: Blue inputs editable. Scenario toggle in D6 drives sell-side tabs. $ in millions.
A4: ($ in millions) | D4: 2024A | E4: 2025A | F4: 2026E | G4: 2027E | H4: 2028E | I4: 2029E | J4: 2030E | K4: 2031E | L4: 2032E
A5: 1 — SCENARIO & MARKET
A6: Scenario (1=Bear, 2=Base, 3=Bull) | D6: 2
A7: Active scenario | D7: =IF(D6=1,"BEAR",IF(D6=2,"BASE","BULL")) -> BASE
A8: Current share price ($) | D8: 224.77
A9: Diluted shares (mm) | D9: 1773
A10: Net debt ($mm) | D10: 63122
A11: Market cap ($mm) | D11: =D8*D9 -> 398517.21
A12: Enterprise value ($mm) | D12: =D11+D10 -> 461639.21
A14: 2 — WACC / DISCOUNT RATE
A15: Risk-free rate | D15: 0.043
A16: Equity risk premium | D16: 0.05
A17: Beta | D17: 0.65
A18: Size premium | D18: 0.005
A19: Cost of equity (CAPM) | D19: =D15+D17*D16+D18 -> 0.0805
A20: Pre-tax cost of debt | D20: 0.048
A21: Weight equity | D21: 0.88
A22: Weight debt | D22: 0.12
A23: Marginal tax rate | D23: 0.15
A24: After-tax cost of debt | D24: =D20*(1-D23) -> 0.0408
A25: WACC | D25: =D21*D19+D22*D24 -> 0.075736
A27: 3 — REVENUE GROWTH (toggle vectors)
A28: Bear: revenue growth % | F28: 0.02 | G28: 0.01 | H28: 0 | I28: -0.01 | J28: 0.01 | K28: 0.02 | L28: 0.02
A29: Base: revenue growth % | F29: 0.06 | G29: 0.05 | H29: 0.045 | I29: 0.04 | J29: 0.035 | K29: 0.03 | L29: 0.03
A30: Bull: revenue growth % | F30: 0.09 | G30: 0.08 | H30: 0.07 | I30: 0.06 | J30: 0.05 | K30: 0.04 | L30: 0.04
A31: ACTIVE revenue growth % | F31: =INDEX(F28:F30,D6) -> 0.06 | G31: =INDEX(G28:G30,D6) -> 0.05 | H31: =INDEX(H28:H30,D6) -> 0.045 | I31: =INDEX(I28:I30,D6) -> 0.04 | J31: =INDEX(J28:J30,D6) -> 0.035 | K31: =INDEX(K28:K30,D6) -> 0.03 | L31: =INDEX(L28:L30,D6) -> 0.03
A33: 4 — MARGIN & TERMINAL
A34: EBIT margin % (active, base path) | F34: 0.34 | G34: 0.345 | H34: 0.348 | I34: 0.35 | J34: 0.35 | K34: 0.35 | L34: 0.35
A35: Tax rate % (normalized) | D35: 0.15
A36: Terminal growth g % | D36: 0.03
A37: Terminal EV/EBIT (x) | D37: 13
A38: Terminal P/E (x) | D38: 12
A39: Terminal P/S (x) | D39: 5
A40: Terminal P/B (x) | D40: 4
A42: 5 — CAPITAL RETURNS
A43: Buybacks ($mm/yr) | D43: 2000
A44: DPS 2026E ($) | D44: 7.05
A45: DPS growth %/yr | D45: 0.055
...

Sheet Fin-Summary
A1: Financial Summary — ABBV
A2: Super-summary, actuals + Base case. $ in millions except per share.
A4: ($ in millions) | B4: 2021A | C4: 2022A | D4: 2023A | E4: 2024A | F4: 2025A | G4: 2026E | H4: 2027E | I4: 2028E | J4: 2029E | K4: 2030E | L4: 2031E | M4: 2032E
A5: INCOME STATEMENT
A6: Sales | B6: ='Fin-Forecast'!B21 -> 56197 | C6: ='Fin-Forecast'!C21 -> 58054 | D6: ='Fin-Forecast'!D21 -> 54318 | E6: ='Fin-Forecast'!E21 -> 56334 | F6: ='Fin-Forecast'!F21 -> 61160 | G6: ='Fin-Forecast'!G21 -> 64829.6 | H6: ='Fin-Forecast'!H21 -> 68071.08 | I6: ='Fin-Forecast'!I21 -> 71134.279 | ... M6: ='Fin-Forecast'!M21 -> 81231.986
A7: Gross profit | B7: ='Fin-Forecast'!B23 -> 39053 | C7: ='Fin-Forecast'!C23 -> 41609 | D7: ='Fin-Forecast'!D23 -> 37668 | E7: ='Fin-Forecast'!E23 -> 39503 | F7: ='Fin-Forecast'!F23 -> 42890 | G7: ='Fin-Forecast'!G23 -> 45380.72 | H7: ='Fin-Forecast'!H23 -> 47649.756 | I7: ='Fin-Forecast'!I23 -> 49793.995 | ... M7: ='Fin-Forecast'!M23 -> 56862.39
A8: EBIT | B8: ='Fin-Forecast'!B25 -> 19749 | C8: ='Fin-Forecast'!C25 -> 22602 | D8: ='Fin-Forecast'!D25 -> 18082 | E8: ='Fin-Forecast'!E25 -> 16625 | F8: ='Fin-Forecast'!F25 -> 20913 | G8: ='Fin-Forecast'!G25 -> 22042.064 | H8: ='Fin-Forecast'!H25 -> 23484.523 | I8: ='Fin-Forecast'!I25 -> 24754.729 | ... M8: ='Fin-Forecast'!M25 -> 28431.195
A9: Net income | B9: ='Fin-Forecast'!B32 -> 11468 | C9: ='Fin-Forecast'!C32 -> 11782 | D9: ='Fin-Forecast'!D32 -> 4820 | E9: ='Fin-Forecast'!E32 -> 4238 | F9: ='Fin-Forecast'!F32 -> 4186 | G9: ='Fin-Forecast'!G32 -> 16158.508 | H9: ='Fin-Forecast'!H32 -> 17461.097 | I9: ='Fin-Forecast'!I32 -> 18617.273 | ... M9: ='Fin-Forecast'!M32 -> 22048.269
A10: NOPAT | B10: ='Fin-Forecast'!B33 -> 16786.65 | C10: ='Fin-Forecast'!C33 -> 19211.7 | D10: ='Fin-Forecast'!D33 -> 15369.7 | E10: ='Fin-Forecast'!E33 -> 14131.25 | F10: ='Fin-Forecast'!F33 -> 17776.05 | G10: ='Fin-Forecast'!G33 -> 18735.754 | H10: ='Fin-Forecast'!H33 -> 19961.844 | I10: ='Fin-Forecast'!I33 -> 21041.52 | ... M10: ='Fin-Forecast'!M33 -> 24166.516
A12: CAPITAL
A13: Invested capital (ex cash) | B13: ='Fin-Capital'!B13 -> 128925.51 | C13: ='Fin-Capital'!C13 -> 121640.25 | D13: ='Fin-Capital'!D13 -> 113417.75 | E13: ='Fin-Capital'!E13 -> 121102.61 | F13: ='Fin-Capital'!F13 -> 120607.55 | G13: ='Fin-Capital'!G13 -> 128353 | H13: ='Fin-Capital'!H13 -> 134770.65 | I13: ='Fin-Capital'!I13 -> 140835.33 | ... M13: ='Fin-Capital'!M13 -> 160827.3
A14: Invested capital (w cash) | B14: ='Fin-Capital'!B14 -> 138755.51 | C14: ='Fin-Capital'!C14 -> 130869.25 | D14: ='Fin-Capital'!D14 -> 126233.75 | E14: ='Fin-Capital'!E14 -> 126657.61 | F14: ='Fin-Capital'!F14 -> 125864.55 | G14: ='Fin-Capital'!G14 -> 133610 | H14: ='Fin-Capital'!H14 -> 140027.65 | I14: ='Fin-Capital'!I14 -> 146092.33 | ... M14: ='Fin-Capital'!M14 -> 166084.3
A15: Short/LT debt | B15: ='Fin-Capital'!B18 -> 77575 | C15: ='Fin-Capital'!C18 -> 64191 | D15: ='Fin-Capital'!D18 -> 60120 | E15: ='Fin-Capital'!E18 -> 67841 | F15: ='Fin-Capital'!F18 -> 68379 | G15: ='Fin-Capital'!G18 -> 66379 | H15: ='Fin-Capital'!H18 -> 64379 | I15: ='Fin-Capital'!I18 -> 62379 | ... M15: ='Fin-Capital'!M18 -> 54379
A17: FREE CASH FLOW (with cash/debt)
A18: FCFF | B18: ='Fin-FCF'!B22 -> 0 | C18: ='Fin-FCF'!C22 -> 27097.96 | D18: ='Fin-FCF'!D22 -> 20005.199 | E18: ='Fin-FCF'!E22 -> 13707.387 | F18: ='Fin-FCF'!F22 -> 18569.114 | G18: ='Fin-FCF'!G22 -> 10990.299 | H18: ='Fin-FCF'!H22 -> 13544.194 | I18: ='Fin-FCF'!I22 -> 14976.84 | ... M18: ='Fin-FCF'!M22 -> 19482.226
A19: FCFE | B19: ='Fin-FCF'!B25 -> 0 | C19: ='Fin-FCF'!C25 -> 11719.86 | D19: ='Fin-FCF'!D25 -> 13928.199 | E19: ='Fin-FCF'!E25 -> 18917.487 | F19: ='Fin-FCF'!F25 -> 16506.964 | G19: ='Fin-FCF'!G25 -> 6413.052 | H19: ='Fin-FCF'!H25 -> 9043.4473 | I19: ='Fin-FCF'!I25 -> 10552.593 | ... M19: ='Fin-FCF'!M25 -> 15363.979
A21: PER SHARE
A22: EPS (diluted) | B22: ='Fin-Forecast'!B35 -> 6.4535734 | C22: ='Fin-Forecast'!C35 -> 6.6265467 | D22: ='Fin-Forecast'!D35 -> 2.7185561 | E22: ='Fin-Forecast'!E35 -> 2.3902989 | F22: ='Fin-Forecast'!F35 -> 2.3609701 | G22: ='Fin-Forecast'!G35 -> 9.1585716 | H22: ='Fin-Forecast'!H35 -> 9.9428785 | I22: ='Fin-Forecast'!I35 -> 10.64788 | ... M22: ='Fin-Forecast'!M35 -> 12.807799
A23: DPS | B23: ='Fin-Forecast'!B36 -> 5.2 | C23: ='Fin-Forecast'!C36 -> 5.64 | D23: ='Fin-Forecast'!D36 -> 5.92 | E23: ='Fin-Forecast'!E36 -> 6.29 | F23: ='Fin-Forecast'!F36 -> 6.65 | G23: ='Fin-Forecast'!G36 -> 7.05 | H23: ='Fin-Forecast'!H36 -> 7.44 | I23: ='Fin-Forecast'!I36 -> 7.85 | ... M23: ='Fin-Forecast'!M36 -> 9.72

Sheet Fin-Forecast
A1: Financial Forecast — ABBV
A2: Bear/Base/Bull assumptions and full income statement. Forward tax normalized to 15%. $mm.
G3: BASE CASE | N3: BULL CASE | U3: BEAR CASE
A4: ($ in millions) | B4: 2021A | C4: 2022A | D4: 2023A | E4: 2024A | F4: 2025A | G4: 2026E | H4: 2027E | I4: 2028E | J4: 2029E | K4: 2030E | L4: 2031E | M4: 2032E | N4: 2026E | O4: 2027E | P4: 2028E | Q4: 2029E | R4: 2030E | S4: 2031E | T4: 2032E | U4: 2026E | V4: 2027E | W4: 2028E | X4: 2029E | Y4: 2030E | Z4: 2031E | AA4: 2032E
A5: INCOME STATEMENT ASSUMPTIONS
A6: Sales growth % | G6: 0.06 | H6: 0.05 | I6: 0.045 | J6: 0.04 | K6: 0.035 | L6: 0.03 | M6: 0.03 | N6: 0.09 | O6: 0.08 | P6: 0.07 | Q6: 0.06 | R6: 0.05 | S6: 0.04 | T6: 0.04 | U6: 0.02 | V6: 0.01 | W6: 0 | X6: -0.01 | Y6: 0.01 | Z6: 0.02 | AA6: 0.02
A7: EBIT margin % | G7: 0.34 | H7: 0.345 | I7: 0.348 | J7: 0.35 | K7: 0.35 | L7: 0.35 | M7: 0.35 | N7: 0.355 | O7: 0.36 | P7: 0.365 | Q7: 0.368 | R7: 0.37 | S7: 0.37 | T7: 0.37 | U7: 0.32 | V7: 0.318 | W7: 0.315 | X7: 0.315 | Y7: 0.315 | Z7: 0.315 | AA7: 0.315
A8: Gross margin % | G8: 0.7 | H8: 0.7 | I8: 0.7 | J8: 0.7 | K8: 0.7 | L8: 0.7 | M8: 0.7 | N8: 0.71 | O8: 0.712 | P8: 0.713 | Q8: 0.714 | R8: 0.715 | S8: 0.715 | T8: 0.715 | U8: 0.69 | V8: 0.688 | W8: 0.686 | X8: 0.685 | Y8: 0.685 | Z8: 0.685 | AA8: 0.685
A9: Tax rate % (normalized) | G9: 0.15 | H9: 0.15 | I9: 0.15 | J9: 0.15 | K9: 0.15 | L9: 0.15 | M9: 0.15 | N9: 0.15 | O9: 0.15 | P9: 0.15 | Q9: 0.15 | R9: 0.15 | S9: 0.15 | T9: 0.15 | U9: 0.15 | V9: 0.15 | W9: 0.15 | X9: 0.15 | Y9: 0.15 | Z9: 0.15 | AA9: 0.15
A10: Rate on debt % | G10: 0.045 | H10: 0.045 | I10: 0.045 | J10: 0.045 | K10: 0.045 | L10: 0.045 | M10: 0.045 | N10: 0.045 | O10: 0.045 | P10: 0.045 | Q10: 0.045 | R10: 0.045 | S10: 0.045 | T10: 0.045 | U10: 0.045 | V10: 0.045 | W10: 0.045 | X10: 0.045 | Y10: 0.045 | Z10: 0.045 | AA10: 0.045
A12: CAPITAL ASSUMPTIONS
A13: Op assets ex cash % of sales | G13: 0.31 | H13: 0.31 | I13: 0.31 | J13: 0.31 | K13: 0.31 | L13: 0.31 | M13: 0.31 | N13: 0.31 | O13: 0.31 | P13: 0.31 | Q13: 0.31 | R13: 0.31 | S13: 0.31 | T13: 0.31 | U13: 0.31 | V13: 0.31 | W13: 0.31 | X13: 0.31 | Y13: 0.31 | Z13: 0.31 | AA13: 0.31
A14: Op liabilities % of sales | G14: 0.182 | H14: 0.182 | I14: 0.182 | J14: 0.182 | K14: 0.182 | L14: 0.182 | M14: 0.182 | N14: 0.182 | O14: 0.182 | P14: 0.182 | Q14: 0.182 | R14: 0.182 | S14: 0.182 | T14: 0.182 | U14: 0.182 | V14: 0.182 | W14: 0.182 | X14: 0.182 | Y14: 0.182 | Z14: 0.182 | AA14: 0.182
A15: NFA turnover (S/NFA) | G15: 0.54 | H15: 0.54 | I15: 0.54 | J15: 0.54 | K15: 0.54 | L15: 0.54 | M15: 0.54 | N15: 0.54 | O15: 0.54 | P15: 0.54 | Q15: 0.54 | R15: 0.54 | S15: 0.54 | T15: 0.54 | U15: 0.54 | V15: 0.54 | W15: 0.54 | X15: 0.54 | Y15: 0.54 | Z15: 0.54 | AA15: 0.54
A16: Buybacks ($mm/yr) | G16: 2000 | H16: 2000 | I16: 2000 | J16: 2000 | K16: 2000 | L16: 2000 | M16: 2000 | N16: 2000 | O16: 2000 | P16: 2000 | Q16: 2000 | R16: 2000 | S16: 2000 | T16: 2000 | U16: 2000 | V16: 2000 | W16: 2000 | X16: 2000 | Y16: 2000 | Z16: 2000 | AA16: 2000
A17: Buyback share price ($) | G17: 230 | H17: 245 | I17: 260 | J17: 275 | K17: 290 | L17: 305 | M17: 320 | N17: 230 | O17: 245 | P17: 260 | Q17: 275 | R17: 290 | S17: 305 | T17: 320 | U17: 230 | V17: 245 | W17: 260 | X17: 275 | Y17: 290 | Z17: 305 | AA17: 320
A18: DPS ($) | G18: 7.05 | H18: 7.44 | I18: 7.85 | J18: 8.28 | K18: 8.73 | L18: 9.21 | M18: 9.72 | N18: 7.05 | O18: 7.44 | P18: 7.85 | Q18: 8.28 | R18: 8.73 | S18: 9.21 | T18: 9.72 | U18: 7.05 | V18: 7.44 | W18: 7.85 | X18: 8.28 | Y18: 8.73 | Z18: 9.21 | AA18: 9.72
A20: INCOME STATEMENT
A21: Sales | B21: 56197 | C21: 58054 | D21: 54318 | E21: 56334 | F21: 61160 | G21: =F21*(1+G6) -> 64829.6 | H21: =G21*(1+H6) -> 68071.08 | I21: =H21*(1+I6) -> 71134.279 | J21: =I21*(1+J6) -> 73979.65 | K21: =J21*(1+K6) -> 76568.937 | L21: =K21*(1+L6) -> 78866.006 | M21: =L21*(1+M6) -> 81231.986 | N21: =F21*(1+N6) -> 66664.4 | O21: =N21*(1+O6) -> 71997.552 | P21: =O21*(1+P6) -> 77037.381 | Q21: =P21*(1+Q6) -> 81659.623 | R21: =Q21*(1+R6) -> 85742.605 | S21: =R21*(1+S6) -> 89172.309 | T21: =S21*(1+T6) -> 92739.201 | U21: =F21*(1+U6) -> 62383.2 | V21: =U21*(1+V6) -> 63007.032 | W21: =V21*(1+W6) -> 63007.032 | X21: =W21*(1+X6) -> 62376.962 | Y21: =X21*(1+Y6) -> 63000.731 | Z21: =Y21*(1+Z6) -> 64260.746 | AA21: =Z21*(1+AA6) -> 65545.961
A22: growth % | C22: =C21/B21-1 -> 0.033044469 | D22: =D21/C21-1 -> -0.064353877 | E22: =E21/D21-1 -> 0.037114769 | F22: =F21/E21-1 -> 0.085667625 | G22: =G21/F21-1 -> 0.06 | H22: =H21/G21-1 -> 0.05 | I22: =I21/H21-1 -> 0.045 | J22: =J21/I21-1 -> 0.04 | ... M22: =M21/L21-1 -> 0.03 | N22: =N21/F21-1 -> 0.09 | O22: =O21/N21-1 -> 0.08 | P22: =P21/O21-1 -> 0.07 | Q22: =Q21/P21-1 -> 0.06 | R22: =R21/Q21-1 -> 0.05 | S22: =S21/R21-1 -> 0.04 | T22: =T21/S21-1 -> 0.04 | U22: =U21/F21-1 -> 0.02 | V22: =V21/U21-1 -> 0.01 | W22: =W21/V21-1 -> 0 | X22: =X21/W21-1 -> -0.01 | Y22: =Y21/X21-1 -> 0.01 | Z22: =Z21/Y21-1 -> 0.02 | AA22: =AA21/Z21-1 -> 0.02
A23: Gross profit | B23: 39053 | C23: 41609 | D23: 37668 | E23: 39503 | F23: 42890 | G23: =G21*G8 -> 45380.72 | H23: =H21*H8 -> 47649.756 | I23: =I21*I8 -> 49793.995 | J23: =J21*J8 -> 51785.755 | K23: =K21*K8 -> 53598.256 | L23: =L21*L8 -> 55206.204 | M23: =M21*M8 -> 56862.39 | N23: =N21*N8 -> 47331.724 | ... AA23: =AA21*AA8 -> 44898.983
A24: Direct costs | B24: =B21-B23 -> 17144 | C24: =C21-C23 -> 16445 | D24: =D21-D23 -> 16650 | E24: =E21-E23 -> 16831 | F24: =F21-F23 -> 18270 | G24: =G21-G23 -> 19448.88 | H24: =H21-H23 -> 20421.324 | I24: =I21-I23 -> 21340.284 | ... AA24: =AA21-AA23 -> 20646.978
A25: EBIT | B25: 19749 | C25: 22602 | D25: 18082 | E25: 16625 | F25: 20913 | G25: =G21*G7 -> 22042.064 | H25: =H21*H7 -> 23484.523 | I25: =I21*I7 -> 24754.729 | J25: =J21*J7 -> 25892.877 | K25: =K21*K7 -> 26799.128 | L25: =L21*L7 -> 27603.102 | M25: =M21*M7 -> 28431.195 | N25: =N21*N7 -> 23665.862 | ... AA25: =AA21*AA7 -> 20646.978
A26: SG&A, R&D, and other | B26: =B23-B25 -> 19304 | C26: =C23-C25 -> 19007 | D26: =D23-D25 -> 19586 | E26: =E23-E25 -> 22878 | F26: =F23-F25 -> 21977 | G26: =G23-G25 -> 23338.656 | H26: =H23-H25 -> 24165.233 | I26: =I23-I25 -> 25039.266 | ... AA26: =AA23-AA25 -> 24252.006
A27: EBIT margin % | B27: =B25/B21 -> 0.35142445 | C27: =C25/C21 -> 0.38932718 | D27: =D25/D21 -> 0.33289149 | E27: =E25/E21 -> 0.29511485 | F27: =F25/F21 -> 0.34193918 | G27: =G25/G21 -> 0.34 | H27: =H25/H21 -> 0.345 | I27: =I25/I21 -> 0.348 | ... AA27: =AA25/AA21 -> 0.315
A28: Total debt (memo) | B28: 77575 | C28: 64191 | D28: 60120 | E28: 67841 | F28: 68379 | G28: 66379 | H28: 64379 | I28: 62379 | J28: 60379 | K28: 58379 | L28: 56379 | M28: 54379 | N28: 66379 | O28: 64379 | P28: 62379 | Q28: 60379 | R28: 58379 | S28: 56379 | T28: 54379 | U28: 66379 | V28: 64379 | W28: 62379 | X28: 60379 | Y28: 58379 | Z28: 56379 | AA28: 54379
A29: Interest and other | B29: 2449 | C29: 2346 | D29: 2360 | E29: 2954 | F29: 3059 | G29: =G10*(G28+F28)/2 -> 3032.055 | H29: =H10*(H28+G28)/2 -> 2942.055 | I29: =I10*(I28+H28)/2 -> 2852.055 | J29: =J10*(J28+I28)/2 -> 2762.055 | K29: =K10*(K28+J28)/2 -> 2672.055 | L29: =L10*(L28+K28)/2 -> 2582.055 | M29: =M10*(M28+L28)/2 -> 2492.055 | N29: =N10*(N28+F28)/2 -> 3032.055 | O29: =O10*(O28+N28)/2 -> 2942.055 | P29: =P10*(P28+O28)/2 -> 2852.055 | Q29: =Q10*(Q28+P28)/2 -> 2762.055 | R29: =R10*(R28+Q28)/2 -> 2672.055 | S29: =S10*(S28+R28)/2 -> 2582.055 | T29: =T10*(T28+S28)/2 -> 2492.055 | U29: =U10*(U28+F28)/2 -> 3032.055 | V29: =V10*(V28+U28)/2 -> 2942.055 | W29: =W10*(W28+V28)/2 -> 2852.055 | X29: =X10*(X28+W28)/2 -> 2762.055 | Y29: =Y10*(Y28+X28)/2 -> 2672.055 | Z29: =Z10*(Z28+Y28)/2 -> 2582.055 | AA29: =AA10*(AA28+Z28)/2 -> 2492.055
A30: EBT | B30: =B25-B29 -> 17300 | C30: =C25-C29 -> 20256 | D30: =D25-D29 -> 15722 | E30: =E25-E29 -> 13671 | F30: =F25-F29 -> 17854 | G30: =G25-G29 -> 19010.009 | H30: =H25-H29 -> 20542.468 | I30: =I25-I29 -> 21902.674 | ... AA30: =AA25-AA29 -> 18154.923
A31: Taxes | B31: 5832 | C31: 8474 | D31: 10902 | E31: 9433 | F31: 13668 | G31: =G30*G9 -> 2851.5014 | H31: =H30*H9 -> 3081.3701 | I31: =I30*I9 -> 3285.4011 | J31: =J30*J9 -> 3469.6234 | K31: =K30*K9 -> 3619.061 | L31: =L30*L9 -> 3753.157 | M31: =M30*M9 -> 3890.871 | N31: =N30*N9 -> 3095.0711 | ... AA31: =AA30*AA9 -> 2723.2384
A32: Net income | B32: 11468 | C32: 11782 | D32: 4820 | E32: 4238 | F32: 4186 | G32: =G30-G31 -> 16158.508 | H32: =H30-H31 -> 17461.097 | I32: =I30-I31 -> 18617.273 | J32: =J30-J31 -> 19661.199 | K32: =K30-K31 -> 20508.012 | L32: =L30-L31 -> 21267.89 | M32: =M30-M31 -> 22048.269 | N32: =N30-N31 -> 17538.736 | ... AA32: =AA30-AA31 -> 15431.684
A33: NOPAT = EBIT×(1-tax) (memo) | B33: =B25*(1-0.15) -> 16786.65 | C33: =C25*(1-0.15) -> 19211.7 | D33: =D25*(1-0.15) -> 15369.7 | E33: =E25*(1-0.15) -> 14131.25 | F33: =F25*(1-0.15) -> 17776.05 | G33: =G25*(1-G9) -> 18735.754 | H33: =H25*(1-H9) -> 19961.844 | I33: =I25*(1-I9) -> 21041.52 | J33: =J25*(1-J9) -> 22008.946 | K33: =K25*(1-K9) -> 22779.259 | L33: =L25*(1-L9) -> 23462.637 | M33: =M25*(1-M9) -> 24166.516 | N33: =N25*(1-N9) -> 20115.983 | ... AA33: =AA25*(1-AA9) -> 17549.931
A34: Diluted shares (mm) | B34: 1777 | C34: 1778 | D34: 1773 | E34: 1773 | F34: 1773 | G34: =F34-G16/G17 -> 1764.3043 | H34: =G34-H16/H17 -> 1756.1411 | I34: =H34-I16/I17 -> 1748.4488 | J34: =I34-J16/J17 -> 1741.176 | K34: =J34-K16/K17 -> 1734.2795 | L34: =K34-L16/L17 -> 1727.7221 | M34: =L34-M16/M17 -> 1721.4721 | N34: =F34-N16/N17 -> 1764.3043 | O34: =N34-O16/O17 -> 1756.1411 | P34: =O34-P16/P17 -> 1748.4488 | Q34: =P34-Q16/Q17 -> 1741.176 | R34: =Q34-R16/R17 -> 1734.2795 | S34: =R34-S16/S17 -> 1727.7221 | T34: =S34-T16/T17 -> 1721.4721 | U34: =F34-U16/U17 -> 1764.3043 | V34: =U34-V16/V17 -> 1756.1411 | W34: =V34-W16/W17 -> 1748.4488 | X34: =W34-X16/X17 -> 1741.176 | Y34: =X34-Y16/Y17 -> 1734.2795 | Z34: =Y34-Z16/Z17 -> 1727.7221 | AA34: =Z34-AA16/AA17 -> 1721.4721
A35: EPS (diluted) | B35: =B32/B34 -> 6.4535734 | C35: =C32/C34 -> 6.6265467 | D35: =D32/D34 -> 2.7185561 | E35: =E32/E34 -> 2.3902989 | F35: =F32/F34 -> 2.3609701 | G35: =G32/G34 -> 9.1585716 | H35: =H32/H34 -> 9.9428785 | I35: =I32/I34 -> 10.64788 | ... AA35: =AA32/AA34 -> 8.9642371
A36: DPS ($) | B36: 5.2 | C36: 5.64 | D36: 5.92 | E36: 6.29 | F36: 6.65 | G36: =G18 -> 7.05 | H36: =H18 -> 7.44 | I36: =I18 -> 7.85 | J36: =J18 -> 8.28 | K36: =K18 -> 8.73 | L36: =L18 -> 9.21 | M36: =M18 -> 9.72 | N36: =N18 -> 7.05 | ... AA36: =AA18 -> 9.72

Sheet Fin-Capital
A1: Capital Structure — ABBV
A2: IMCP invested-capital framework. NOWC + NFA = IC. NFA carries Allergan intangibles. $mm.
G3: BASE CASE | N3: BULL CASE | U3: BEAR CASE
A4: ($ in millions) | B4: 2021A | C4: 2022A | D4: 2023A | E4: 2024A | F4: 2025A | G4: 2026E | H4: 2027E | I4: 2028E | J4: 2029E | K4: 2030E | L4: 2031E | M4: 2032E | N4: 2026E | O4: 2027E | P4: 2028E | Q4: 2029E | R4: 2030E | S4: 2031E | T4: 2032E | U4: 2026E | V4: 2027E | W4: 2028E | X4: 2029E | Y4: 2030E | Z4: 2031E | AA4: 2032E
A5: OPERATING CAPITAL
A6: Cash & equivalents | B6: 9830 | C6: 9229 | D6: 12816 | E6: 5555 | F6: 5257 | G6: =F6 -> 5257 | H6: =F6 -> 5257 | I6: =F6 -> 5257 | J6: =F6 -> 5257 | K6: =F6 -> 5257 | L6: =F6 -> 5257 | M6: =F6 -> 5257 | N6: =F6 -> 5257 | O6: =F6 -> 5257 | P6: =F6 -> 5257 | Q6: =F6 -> 5257 | R6: =F6 -> 5257 | S6: =F6 -> 5257 | T6: =F6 -> 5257 | U6: =F6 -> 5257 | V6: =F6 -> 5257 | W6: =F6 -> 5257 | X6: =F6 -> 5257 | Y6: =F6 -> 5257 | Z6: =F6 -> 5257 | AA6: =F6 -> 5257
A7: Operating assets ex cash | B7: 15442.598 | C7: 16893.242 | D7: 17708.914 | E7: 18079.27 | F7: 19342.301 | G7: ='Fin-Forecast'!G21*'Fin-Forecast'!G13 -> 20097.176 | H7: ='Fin-Forecast'!H21*'Fin-Forecast'!H13 -> 21102.035 | I7: ='Fin-Forecast'!I21*'Fin-Forecast'!I13 -> 22051.626 | J7: ='Fin-Forecast'!J21*'Fin-Forecast'!J13 -> 22933.691 | K7: ='Fin-Forecast'!K21*'Fin-Forecast'!K13 -> 23736.371 | L7: ='Fin-Forecast'!L21*'Fin-Forecast'!L13 -> 24448.462 | M7: ='Fin-Forecast'!M21*'Fin-Forecast'!M13 -> 25181.916 | N7: ='Fin-Forecast'!N21*'Fin-Forecast'!N13 -> 20665.964 | ... AA7: ='Fin-Forecast'!AA21*'Fin-Forecast'!AA13 -> 20319.248
A8: Operating assets (total) | B8: =B6+B7 -> 25272.598 | C8: =C6+C7 -> 26122.242 | D8: =D6+D7 -> 30524.914 | E8: =E6+E7 -> 23634.27 | F8: =F6+F7 -> 24599.301 | G8: =G6+G7 -> 25354.176 | H8: =H6+H7 -> 26359.035 | I8: =I6+I7 -> 27308.626 | ... AA8: =AA6+AA7 -> 25576.248
A9: Operating liabilities | B9: 10583.342 | C9: 10838.452 | D9: 11193.151 | E9: 11320.088 | F9: 11153.452 | G9: ='Fin-Forecast'!G21*'Fin-Forecast'!G14 -> 11798.987 | H9: ='Fin-Forecast'!H21*'Fin-Forecast'!H14 -> 12388.937 | I9: ='Fin-Forecast'!I21*'Fin-Forecast'!I14 -> 12946.439 | J9: ='Fin-Forecast'!J21*'Fin-Forecast'!J14 -> 13464.296 | K9: ='Fin-Forecast'!K21*'Fin-Forecast'!K14 -> 13935.547 | L9: ='Fin-Forecast'!L21*'Fin-Forecast'!L14 -> 14353.613 | M9: ='Fin-Forecast'!M21*'Fin-Forecast'!M14 -> 14784.221 | N9: ='Fin-Forecast'!N21*'Fin-Forecast'!N14 -> 12132.921 | ... AA9: ='Fin-Forecast'!AA21*'Fin-Forecast'!AA14 -> 11929.365
A10: NOWC (incl cash) | B10: =B8-B9 -> 14689.255 | C10: =C8-C9 -> 15283.79 | D10: =D8-D9 -> 19331.763 | E10: =E8-E9 -> 12314.182 | F10: =F8-F9 -> 13445.849 | G10: =G8-G9 -> 13555.189 | H10: =H8-H9 -> 13970.098 | I10: =I8-I9 -> 14362.188 | ... AA10: =AA8-AA9 -> 13646.883
A11: NWC (ex cash) | B11: =B10-B6 -> 4859.2555 | C11: =C10-C6 -> 6054.7904 | D11: =D10-D6 -> 6515.763 | E11: =E10-E6 -> 6759.1822 | F11: =F10-F6 -> 8188.8493 | G11: =G10-G6 -> 8298.1888 | H11: =H10-H6 -> 8713.0982 | I11: =I10-I6 -> 9105.1877 | ... AA11: =AA10-AA6 -> 8389.883
A12: NFA (net fixed assets) | B12: 124066.25 | C12: 115585.46 | D12: 106901.99 | E12: 114343.43 | F12: 112418.7 | G12: ='Fin-Forecast'!G21/'Fin-Forecast'!G15 -> 120054.81 | H12: ='Fin-Forecast'!H21/'Fin-Forecast'!H15 -> 126057.56 | I12: ='Fin-Forecast'!I21/'Fin-Forecast'!I15 -> 131730.15 | J12: ='Fin-Forecast'!J21/'Fin-Forecast'!J15 -> 136999.35 | K12: ='Fin-Forecast'!K21/'Fin-Forecast'!K15 -> 141794.33 | L12: ='Fin-Forecast'!L21/'Fin-Forecast'!L15 -> 146048.16 | M12: ='Fin-Forecast'!M21/'Fin-Forecast'!M15 -> 150429.6 | N12: ='Fin-Forecast'!N21/'Fin-Forecast'!N15 -> 123452.59 | ... AA12: ='Fin-Forecast'!AA21/'Fin-Forecast'!AA15 -> 121381.41
A13: Invested capital (ex cash) | B13: =B11+B12 -> 128925.51 | C13: =C11+C12 -> 121640.25 | D13: =D11+D12 -> 113417.75 | E13: =E11+E12 -> 121102.61 | F13: =F11+F12 -> 120607.55 | G13: =G11+G12 -> 128353 | H13: =H11+H12 -> 134770.65 | I13: =I11+I12 -> 140835.33 | ... AA13: =AA11+AA12 -> 129771.29
A14: Invested capital (with cash) | B14: =B10+B12 -> 138755.51 | C14: =C10+C12 -> 130869.25 | D14: =D10+D12 -> 126233.75 | E14: =E10+E12 -> 126657.61 | F14: =F10+F12 -> 125864.55 | G14: =G10+G12 -> 133610 | H14: =H10+H12 -> 140027.65 | I14: =I10+I12 -> 146092.33 | ... AA14: =AA10+AA12 -> 135028.29
A15: Total assets | B15: 146529 | C15: 138805 | D15: 134711 | E15: 135161 | F15: 133960 | G15: =G8+G12 -> 145408.99 | H15: =H8+H12 -> 152416.59 | I15: =I8+I12 -> 159038.77 | J15: =J8+J12 -> 165190.04 | K15: =K8+K12 -> 170787.7 | L15: =L8+L12 -> 175753.62 | M15: =M8+M12 -> 180868.52 | N15: =N8+N12 -> 149375.56 | ... AA15: =AA8+AA12 -> 146957.66
A17: SUPPLIED CAPITAL
A18: Short/LT debt | B18: 77575 | C18: 64191 | D18: 60120 | E18: 67841 | F18: 68379 | G18: =F18-2000 -> 66379 | H18: =G18-2000 -> 64379 | I18: =H18-2000 -> 62379 | J18: =I18-2000 -> 60379 | K18: =J18-2000 -> 58379 | L18: =K18-2000 -> 56379 | M18: =L18-2000 -> 54379 | N18: =F18-2000 -> 66379 | O18: =N18-2000 -> 64379 | P18: =O18-2000 -> 62379 | Q18: =P18-2000 -> 60379 | R18: =Q18-2000 -> 58379 | S18: =R18-2000 -> 56379 | T18: =S18-2000 -> 54379 | U18: =F18-2000 -> 66379 | V18: =U18-2000 -> 64379 | W18: =V18-2000 -> 62379 | X18: =W18-2000 -> 60379 | Y18: =X18-2000 -> 58379 | Z18: =Y18-2000 -> 56379 | AA18: =Z18-2000 -> 54379
A19: Other liabilities | B19: 42934.658 | C19: 46488.548 | D19: 53000.849 | E19: 52635.912 | F19: 57655.548 | G19: =F19 -> 57655.548 | H19: =F19 -> 57655.548 | I19: =F19 -> 57655.548 | J19: =F19 -> 57655.548 | K19: =F19 -> 57655.548 | L19: =F19 -> 57655.548 | M19: =F19 -> 57655.548 | N19: =F19 -> 57655.548 | O19: =F19 -> 57655.548 | P19: =F19 -> 57655.548 | Q19: =F19 -> 57655.548 | R19: =F19 -> 57655.548 | S19: =F19 -> 57655.548 | T19: =F19 -> 57655.548 | U19: =F19 -> 57655.548 | V19: =F19 -> 57655.548 | W19: =F19 -> 57655.548 | X19: =F19 -> 57655.548 | Y19: =F19 -> 57655.548 | Z19: =F19 -> 57655.548 | AA19: =F19 -> 57655.548
A20: Equity | B20: 15408 | C20: 17254 | D20: 10360 | E20: 3325 | F20: -3270 | G20: =F20+'Fin-Forecast'!G32-'Fin-Forecast'!G36*'Fin-Forecast'!G34-'Fin-Forecast'!G16 -> -1549.838 | H20: =G20+'Fin-Forecast'!H32-'Fin-Forecast'!H36*'Fin-Forecast'!H34-'Fin-Forecast'!H16 -> 845.5698 | I20: =H20+'Fin-Forecast'!I32-'Fin-Forecast'!I36*'Fin-Forecast'!I34-'Fin-Forecast'!I16 -> 3737.5198 | J20: =I20+'Fin-Forecast'!J32-'Fin-Forecast'!J36*'Fin-Forecast'!J34-'Fin-Forecast'!J16 -> 6981.7812 | K20: =J20+'Fin-Forecast'!K32-'Fin-Forecast'!K36*'Fin-Forecast'!K34-'Fin-Forecast'!K16 -> 10349.533 | L20: =K20+'Fin-Forecast'!L32-'Fin-Forecast'!L36*'Fin-Forecast'!L34-'Fin-Forecast'!L16 -> 13705.103 | M20: =L20+'Fin-Forecast'!M32-'Fin-Forecast'!M36*'Fin-Forecast'!M34-'Fin-Forecast'!M16 -> 17020.663 | N20: =F20+'Fin-Forecast'!N32-'Fin-Forecast'!N36*'Fin-Forecast'!N34-'Fin-Forecast'!N16 -> -169.6097 | O20: =N20+'Fin-Forecast'!O32-'Fin-Forecast'!O36*'Fin-Forecast'!O34-'Fin-Forecast'!O16 -> 4295.2048 | P20: =O20+'Fin-Forecast'!P32-'Fin-Forecast'!P36*'Fin-Forecast'!P34-'Fin-Forecast'!P16 -> 10046.483 | Q20: =P20+'Fin-Forecast'!Q32-'Fin-Forecast'!Q36*'Fin-Forecast'!Q34-'Fin-Forecast'!Q16 -> 16824.928 | R20: =Q20+'Fin-Forecast'!R32-'Fin-Forecast'!R36*'Fin-Forecast'!R34-'Fin-Forecast'!R16 -> 24379.471 | S20: =R20+'Fin-Forecast'!S32-'Fin-Forecast'!S36*'Fin-Forecast'!S34-'Fin-Forecast'!S16 -> 32317.094 | T20: =S20+'Fin-Forecast'!T32-'Fin-Forecast'!T36*'Fin-Forecast'!T34-'Fin-Forecast'!T16 -> 40632.617 | U20: =F20+'Fin-Forecast'!U32-'Fin-Forecast'!U36*'Fin-Forecast'!U34-'Fin-Forecast'!U16 -> -3317.362 | V20: =U20+'Fin-Forecast'!V32-'Fin-Forecast'!V36*'Fin-Forecast'!V34-'Fin-Forecast'!V16 -> -3852.9977 | W20: =V20+'Fin-Forecast'!W32-'Fin-Forecast'!W36*'Fin-Forecast'!W34-'Fin-Forecast'!W16 -> -5132.4345 | X20: =W20+'Fin-Forecast'!X32-'Fin-Forecast'!X36*'Fin-Forecast'!X34-'Fin-Forecast'!X16 -> -7195.6874 | Y20: =X20+'Fin-Forecast'!Y32-'Fin-Forecast'!Y36*'Fin-Forecast'!Y34-'Fin-Forecast'!Y16 -> -9738.7483 | Z20: =Y20+'Fin-Forecast'!Z32-'Fin-Forecast'!Z36*'Fin-Forecast'!Z34-'Fin-Forecast'!Z16 -> -12640.001 | AA20: =Z20+'Fin-Forecast'!AA32-'Fin-Forecast'!AA36*'Fin-Forecast'!AA34-'Fin-Forecast'!AA16 -> -15941.026
A21: Total supplied capital | B21: =B18+B19+B20 -> 135917.66 | C21: =C18+C19+C20 -> 127933.55 | D21: =D18+D19+D20 -> 123480.85 | E21: =E18+E19+E20 -> 123801.91 | F21: =F18+F19+F20 -> 122764.55 | G21: =G18+G19+G20 -> 122484.71 | H21: =H18+H19+H20 -> 122880.12 | I21: =I18+I19+I20 -> 123772.07 | ... AA21: =AA18+AA19+AA20 -> 96093.522
A23: TURNOVER MEMOS
A24: NFA turnover (S/NFA) | B24: ='Fin-Forecast'!B21/B12 -> 0.4529596 | C24: ='Fin-Forecast'!C21/C12 -> 0.50226042 | D24: ='Fin-Forecast'!D21/D12 -> 0.5081103 | E24: ='Fin-Forecast'!E21/E12 -> 0.49267369 | F24: ='Fin-Forecast'!F21/F12 -> 0.54403761 | G24: ='Fin-Forecast'!G21/G12 -> 0.54 | H24: ='Fin-Forecast'!H21/H12 -> 0.54 | I24: ='Fin-Forecast'!I21/I12 -> 0.54 | ... AA24: ='Fin-Forecast'!AA21/AA12 -> 0.54
A25: IC turnover ex cash (S/IC) | B25: ='Fin-Forecast'!B21/B13 -> 0.43588737 | C25: ='Fin-Forecast'!C21/C13 -> 0.4772598 | D25: ='Fin-Forecast'!D21/D13 -> 0.47891975 | E25: ='Fin-Forecast'!E21/E13 -> 0.46517576 | F25: ='Fin-Forecast'!F21/F13 -> 0.50709927 | G25: ='Fin-Forecast'!G21/G13 -> 0.5050883 | H25: ='Fin-Forecast'!H21/H13 -> 0.5050883 | I25: ='Fin-Forecast'!I21/I13 -> 0.5050883 | ... AA25: ='Fin-Forecast'!AA21/AA13 -> 0.5050883

Sheet Fin-Ratios
A1: Ratios — ABBV
A2: Profitability, activity, solvency, ROIC decomposition, ROE, SGR. Actuals + Base case.
A4: ($ in millions) | B4: 2021A | C4: 2022A | D4: 2023A | E4: 2024A | F4: 2025A | G4: 2026E | H4: 2027E | I4: 2028E | J4: 2029E | K4: 2030E | L4: 2031E | M4: 2032E
A5: PROFITABILITY
A6: Gross margin | B6: ='Fin-Forecast'!B23/'Fin-Forecast'!B21 -> 0.69493033 | C6: ='Fin-Forecast'!C23/'Fin-Forecast'!C21 -> 0.71672925 | D6: ='Fin-Forecast'!D23/'Fin-Forecast'!D21 -> 0.69347178 | E6: ='Fin-Forecast'!E23/'Fin-Forecast'!E21 -> 0.70122839 | F6: ='Fin-Forecast'!F23/'Fin-Forecast'!F21 -> 0.70127534 | G6: ='Fin-Forecast'!G23/'Fin-Forecast'!G21 -> 0.7 | H6: ='Fin-Forecast'!H23/'Fin-Forecast'!H21 -> 0.7 | I6: ='Fin-Forecast'!I23/'Fin-Forecast'!I21 -> 0.7 | ... M6: ='Fin-Forecast'!M23/'Fin-Forecast'!M21 -> 0.7
A7: Operating (EBIT) margin | B7: ='Fin-Forecast'!B25/'Fin-Forecast'!B21 -> 0.35142445 | C7: ='Fin-Forecast'!C25/'Fin-Forecast'!C21 -> 0.38932718 | D7: ='Fin-Forecast'!D25/'Fin-Forecast'!D21 -> 0.33289149 | E7: ='Fin-Forecast'!E25/'Fin-Forecast'!E21 -> 0.29511485 | F7: ='Fin-Forecast'!F25/'Fin-Forecast'!F21 -> 0.34193918 | G7: ='Fin-Forecast'!G25/'Fin-Forecast'!G21 -> 0.34 | H7: ='Fin-Forecast'!H25/'Fin-Forecast'!H21 -> 0.345 | I7: ='Fin-Forecast'!I25/'Fin-Forecast'!I21 -> 0.348 | ... M7: ='Fin-Forecast'!M25/'Fin-Forecast'!M21 -> 0.35
A8: Net profit margin | B8: ='Fin-Forecast'!B32/'Fin-Forecast'!B21 -> 0.20406783 | C8: ='Fin-Forecast'!C32/'Fin-Forecast'!C21 -> 0.20294898 | D8: ='Fin-Forecast'!D32/'Fin-Forecast'!D21 -> 0.088736699 | E8: ='Fin-Forecast'!E32/'Fin-Forecast'!E21 -> 0.075229879 | F8: ='Fin-Forecast'!F32/'Fin-Forecast'!F21 -> 0.068443427 | G8: ='Fin-Forecast'!G32/'Fin-Forecast'!G21 -> 0.24924583 | H8: ='Fin-Forecast'!H32/'Fin-Forecast'!H21 -> 0.25651271 | I8: ='Fin-Forecast'!I32/'Fin-Forecast'!I21 -> 0.26172013 | ... M8: ='Fin-Forecast'!M32/'Fin-Forecast'!M21 -> 0.27142349
A10: SOLVENCY
A11: Debt to assets | B11: ='Fin-Capital'!B18/'Fin-Capital'!B15 -> 0.52941738 | C11: ='Fin-Capital'!C18/'Fin-Capital'!C15 -> 0.46245452 | D11: ='Fin-Capital'!D18/'Fin-Capital'!D15 -> 0.44628872 | E11: ='Fin-Capital'!E18/'Fin-Capital'!E15 -> 0.50192733 | F11: ='Fin-Capital'!F18/'Fin-Capital'!F15 -> 0.51044342 | G11: ='Fin-Capital'!G18/'Fin-Capital'!G15 -> 0.45649859 | H11: ='Fin-Capital'!H18/'Fin-Capital'!H15 -> 0.4223884 | I11: ='Fin-Capital'!I18/'Fin-Capital'!I15 -> 0.39222511 | ... M11: ='Fin-Capital'!M18/'Fin-Capital'!M15 -> 0.30065486
A12: Debt to EBIT | B12: ='Fin-Capital'!B18/'Fin-Forecast'!B25 -> 3.928047 | C12: ='Fin-Capital'!C18/'Fin-Forecast'!C25 -> 2.8400584 | D12: ='Fin-Capital'!D18/'Fin-Forecast'!D25 -> 3.3248534 | E12: ='Fin-Capital'!E18/'Fin-Forecast'!E25 -> 4.0806617 | F12: ='Fin-Capital'!F18/'Fin-Forecast'!F25 -> 3.2696887 | G12: ='Fin-Capital'!G18/'Fin-Forecast'!G25 -> 3.0114693 | H12: ='Fin-Capital'!H18/'Fin-Forecast'!H25 -> 2.7413374 | I12: ='Fin-Capital'!I18/'Fin-Forecast'!I25 -> 2.5198822 | ... M12: ='Fin-Capital'!M18/'Fin-Forecast'!M25 -> 1.9126526
A13: EBIT / interest (coverage) | B13: ='Fin-Forecast'!B25/'Fin-Forecast'!B29 -> 8.0641078 | C13: ='Fin-Forecast'!C25/'Fin-Forecast'!C29 -> 9.6342711 | D13: ='Fin-Forecast'!D25/'Fin-Forecast'!D29 -> 7.6618644 | E13: ='Fin-Forecast'!E25/'Fin-Forecast'!E29 -> 5.6279621 | F13: ='Fin-Forecast'!F25/'Fin-Forecast'!F29 -> 6.8365479 | G13: ='Fin-Forecast'!G25/'Fin-Forecast'!G29 -> 7.2696782 | H13: ='Fin-Forecast'!H25/'Fin-Forecast'!H29 -> 7.9823534 | I13: ='Fin-Forecast'!I25/'Fin-Forecast'!I29 -> 8.6796114 | ... M13: ='Fin-Forecast'!M25/'Fin-Forecast'!M29 -> 11.408735
A14: Debt / invested capital | B14: ='Fin-Capital'!B18/'Fin-Capital'!B13 -> 0.60170405 | C14: ='Fin-Capital'!C18/'Fin-Capital'!C13 -> 0.52771185 | D14: ='Fin-Capital'!D18/'Fin-Capital'!D13 -> 0.53007576 | E14: ='Fin-Capital'!E18/'Fin-Capital'!E13 -> 0.56019436 | F14: ='Fin-Capital'!F18/'Fin-Capital'!F13 -> 0.56695457 | G14: ='Fin-Capital'!G18/'Fin-Capital'!G13 -> 0.51715969 | H14: ='Fin-Capital'!H18/'Fin-Capital'!H13 -> 0.47769302 | I14: ='Fin-Capital'!I18/'Fin-Capital'!I13 -> 0.44292152 | ... M14: ='Fin-Capital'!M18/'Fin-Capital'!M13 -> 0.33812046
A16: ROIC DECOMPOSITION
A17: Method 1 — Avg IC ex cash
A18: NOPAT / sales | B18: ='Fin-Forecast'!B33/'Fin-Forecast'!B21 -> 0.29871079 | C18: ='Fin-Forecast'!C33/'Fin-Forecast'!C21 -> 0.3309281 | D18: ='Fin-Forecast'!D33/'Fin-Forecast'!D21 -> 0.28295777 | E18: ='Fin-Forecast'!E33/'Fin-Forecast'!E21 -> 0.25084762 | F18: ='Fin-Forecast'!F33/'Fin-Forecast'!F21 -> 0.2906483 | G18: ='Fin-Forecast'!G33/'Fin-Forecast'!G21 -> 0.289 | H18: ='Fin-Forecast'!H33/'Fin-Forecast'!H21 -> 0.29325 | I18: ='Fin-Forecast'!I33/'Fin-Forecast'!I21 -> 0.2958 | ... M18: ='Fin-Forecast'!M33/'Fin-Forecast'!M21 -> 0.2975
A19: Sales / avg IC ex cash | C19: ='Fin-Forecast'!C21/(('Fin-Capital'!C13+'Fin-Capital'!B13)/2) -> 0.46338335 | D19: ='Fin-Forecast'!D21/(('Fin-Capital'!D13+'Fin-Capital'!C13)/2) -> 0.46216679 | E19: ='Fin-Forecast'!E21/(('Fin-Capital'!E13+'Fin-Capital'!D13)/2) -> 0.48041884 | F19: ='Fin-Forecast'!F21/(('Fin-Capital'!F13+'Fin-Capital'!E13)/2) -> 0.50606065 | G19: ='Fin-Forecast'!G21/(('Fin-Capital'!G13+'Fin-Capital'!F13)/2) -> 0.52080219 | H19: ='Fin-Forecast'!H21/(('Fin-Capital'!H13+'Fin-Capital'!G13)/2) -> 0.51740752 | I19: ='Fin-Forecast'!I21/(('Fin-Capital'!I13+'Fin-Capital'!H13)/2) -> 0.51620271 | J19: ='Fin-Forecast'!J21/(('Fin-Capital'!J13+'Fin-Capital'!I13)/2) -> 0.51499199 | ... M19: ='Fin-Forecast'!M21/(('Fin-Capital'!M13+'Fin-Capital'!L13)/2) -> 0.51255266
A20: ROIC (avg IC ex cash) | C20: =C18*C19 -> 0.15334657 | D20: =D18*D19 -> 0.13077368 | E20: =E18*E19 -> 0.12051192 | F20: =F18*F19 -> 0.14708567 | G20: =G18*G19 -> 0.15051183 | H20: =H18*H19 -> 0.15172976 | I20: =I18*I19 -> 0.15269276 | J20: =J18*J19 -> 0.15321012 | ... M20: =M18*M19 -> 0.15248442
A21: Method 2 — EOY IC ex cash
A22: Sales / EOY IC ex cash | B22: ='Fin-Forecast'!B21/'Fin-Capital'!B13 -> 0.43588737 | C22: ='Fin-Forecast'!C21/'Fin-Capital'!C13 -> 0.4772598 | D22: ='Fin-Forecast'!D21/'Fin-Capital'!D13 -> 0.47891975 | E22: ='Fin-Forecast'!E21/'Fin-Capital'!E13 -> 0.46517576 | F22: ='Fin-Forecast'!F21/'Fin-Capital'!F13 -> 0.50709927 | G22: ='Fin-Forecast'!G21/'Fin-Capital'!G13 -> 0.5050883 | H22: ='Fin-Forecast'!H21/'Fin-Capital'!H13 -> 0.5050883 | I22: ='Fin-Forecast'!I21/'Fin-Capital'!I13 -> 0.5050883 | ... M22: ='Fin-Forecast'!M21/'Fin-Capital'!M13 -> 0.5050883
A23: ROIC (EOY IC ex cash) | B23: =B18*B22 -> 0.13020426 | C23: =C18*C22 -> 0.15793868 | D23: =D18*D22 -> 0.13551406 | E23: =E18*E22 -> 0.11668823 | F23: =F18*F22 -> 0.14738754 | G23: =G18*G22 -> 0.14597052 | H23: =H18*H22 -> 0.14811714 | I23: =I18*I22 -> 0.14940512 | ... M23: =M18*M22 -> 0.15026377
A25: EVA SPREAD
A26: ROIC (avg IC ex cash) | C26: =C20 -> 0.15334657 | D26: =D20 -> 0.13077368 | E26: =E20 -> 0.12051192 | F26: =F20 -> 0.14708567 | G26: =G20 -> 0.15051183 | H26: =H20 -> 0.15172976 | I26: =I20 -> 0.15269276 | J26: =J20 -> 0.15321012 | ... M26: =M20 -> 0.15248442
A27: WACC | B27: =Drivers!D25 -> 0.075736 | C27: =Drivers!D25 -> 0.075736 | D27: =Drivers!D25 -> 0.075736 | E27: =Drivers!D25 -> 0.075736 | F27: =Drivers!D25 -> 0.075736 | G27: =Drivers!D25 -> 0.075736 | H27: =Drivers!D25 -> 0.075736 | I27: =Drivers!D25 -> 0.075736 | J27: =Drivers!D25 -> 0.075736 | K27: =Drivers!D25 -> 0.075736 | L27: =Drivers!D25 -> 0.075736 | M27: =Drivers!D25 -> 0.075736
A28: EVA spread (ROIC - WACC) | C28: =C20-C27 -> 0.077610573 | D28: =D20-D27 -> 0.055037683 | E28: =E20-E27 -> 0.044775924 | F28: =F20-F27 -> 0.071349666 | G28: =G20-G27 -> 0.074775832 | H28: =H20-H27 -> 0.075993756 | I28: =I20-I27 -> 0.076956761 | J28: =J20-J27 -> 0.077474117 | ... M28: =M20-M27 -> 0.076748415
A30: ROE (DuPont)
A31: 5-stage:
A32: EBIT / Sales | B32: ='Fin-Forecast'!B25/'Fin-Forecast'!B21 -> 0.35142445 | C32: ='Fin-Forecast'!C25/'Fin-Forecast'!C21 -> 0.38932718 | D32: ='Fin-Forecast'!D25/'Fin-Forecast'!D21 -> 0.33289149 | E32: ='Fin-Forecast'!E25/'Fin-Forecast'!E21 -> 0.29511485 | F32: ='Fin-Forecast'!F25/'Fin-Forecast'!F21 -> 0.34193918 | G32: ='Fin-Forecast'!G25/'Fin-Forecast'!G21 -> 0.34 | H32: ='Fin-Forecast'!H25/'Fin-Forecast'!H21 -> 0.345 | I32: ='Fin-Forecast'!I25/'Fin-Forecast'!I21 -> 0.348 | ... M32: ='Fin-Forecast'!M25/'Fin-Forecast'!M21 -> 0.35
A33: Sales / avg Assets | C33: ='Fin-Forecast'!C21/(('Fin-Capital'!C15+'Fin-Capital'!B15)/2) -> 0.40691961 | D33: ='Fin-Forecast'!D21/(('Fin-Capital'!D15+'Fin-Capital'!C15)/2) -> 0.39718335 | E33: ='Fin-Forecast'!E21/(('Fin-Capital'!E15+'Fin-Capital'!D15)/2) -> 0.41748681 | F33: ='Fin-Forecast'!F21/(('Fin-Capital'!F15+'Fin-Capital'!E15)/2) -> 0.45451674 | G33: ='Fin-Forecast'!G21/(('Fin-Capital'!G15+'Fin-Capital'!F15)/2) -> 0.4641145 | H33: ='Fin-Forecast'!H21/(('Fin-Capital'!H15+'Fin-Capital'!G15)/2) -> 0.45712044 | I33: ='Fin-Forecast'!I21/(('Fin-Capital'!I15+'Fin-Capital'!H15)/2) -> 0.45678635 | J33: ='Fin-Forecast'!J21/(('Fin-Capital'!J15+'Fin-Capital'!I15)/2) -> 0.45634223 | ... M33: ='Fin-Forecast'!M21/(('Fin-Capital'!M15+'Fin-Capital'!L15)/2) -> 0.45556334
A34: EBT / EBIT | B34: ='Fin-Forecast'!B30/'Fin-Forecast'!B25 -> 0.87599372 | C34: ='Fin-Forecast'!C30/'Fin-Forecast'!C25 -> 0.89620388 | D34: ='Fin-Forecast'!D30/'Fin-Forecast'!D25 -> 0.86948346 | E34: ='Fin-Forecast'!E30/'Fin-Forecast'!E25 -> 0.82231579 | F34: ='Fin-Forecast'!F30/'Fin-Forecast'!F25 -> 0.85372735 | G34: ='Fin-Forecast'!G30/'Fin-Forecast'!G25 -> 0.86244233 | H34: ='Fin-Forecast'!H30/'Fin-Forecast'!H25 -> 0.87472366 | I34: ='Fin-Forecast'!I30/'Fin-Forecast'!I25 -> 0.88478747 | ... M34: ='Fin-Forecast'!M30/'Fin-Forecast'!M25 -> 0.91234786
A35: NI / EBT | B35: ='Fin-Forecast'!B32/'Fin-Forecast'!B30 -> 0.66289017 | C35: ='Fin-Forecast'!C32/'Fin-Forecast'!C30 -> 0.58165482 | D35: ='Fin-Forecast'!D32/'Fin-Forecast'!D30 -> 0.30657677 | E35: ='Fin-Forecast'!E32/'Fin-Forecast'!E30 -> 0.30999927 | F35: ='Fin-Forecast'!F32/'Fin-Forecast'!F30 -> 0.23445726 | G35: ='Fin-Forecast'!G32/'Fin-Forecast'!G30 -> 0.85 | H35: ='Fin-Forecast'!H32/'Fin-Forecast'!H30 -> 0.85 | I35: ='Fin-Forecast'!I32/'Fin-Forecast'!I30 -> 0.85 | ... M35: ='Fin-Forecast'!M32/'Fin-Forecast'!M30 -> 0.85
A36: ROA (= product) | C36: =C32*C33*C34*C35 -> 0.082583919 | D36: =D32*D33*D34*D35 -> 0.035244739 | E36: =E32*E33*E34*E35 -> 0.031407482 | F36: =F32*F33*F34*F35 -> 0.031108683 | G36: =G32*G33*G34*G35 -> 0.11567861 | H36: =H32*H33*H34*H35 -> 0.1172572 | I36: =I32*I33*I34*I35 -> 0.11955018 | J36: =J32*J33*J34*J35 -> 0.12127978 | ... M36: =M32*M33*M34*M35 -> 0.12365059
A37: avg Assets / avg Equity | C37: =(('Fin-Capital'!C15+'Fin-Capital'!B15)/2)/(('Fin-Capital'!C20+'Fin-Capital'!B20)/2) -> 8.7359623 | D37: =(('Fin-Capital'!D15+'Fin-Capital'!C15)/2)/(('Fin-Capital'!D20+'Fin-Capital'!C20)/2) -> 9.9049757 | E37: =(('Fin-Capital'!E15+'Fin-Capital'!D15)/2)/(('Fin-Capital'!E20+'Fin-Capital'!D20)/2) -> 19.720278 | F37: =(('Fin-Capital'!F15+'Fin-Capital'!E15)/2)/(('Fin-Capital'!F20+'Fin-Capital'!E20)/2) -> 4893.1091 | G37: =(('Fin-Capital'!G15+'Fin-Capital'!F15)/2)/(('Fin-Capital'!G20+'Fin-Capital'!F20)/2) -> -57.96232 | H37: =(('Fin-Capital'!H15+'Fin-Capital'!G15)/2)/(('Fin-Capital'!H20+'Fin-Capital'!G20)/2) -> -422.8866 | I37: =(('Fin-Capital'!I15+'Fin-Capital'!H15)/2)/(('Fin-Capital'!I20+'Fin-Capital'!H20)/2) -> 67.957511 | J37: =(('Fin-Capital'!J15+'Fin-Capital'!I15)/2)/(('Fin-Capital'!J20+'Fin-Capital'!I20)/2) -> 30.247198 | ... M37: =(('Fin-Capital'!M15+'Fin-Capital'!L15)/2)/(('Fin-Capital'!M20+'Fin-Capital'!L20)/2) -> 11.606615
A38: ROE (5-stage) | C38: =C36*C37 -> 0.72145 | D38: =D36*D37 -> 0.34909828 | E38: =E36*E37 -> 0.61936427 | F38: =F36*F37 -> 152.21818 | G38: =G36*G37 -> -6.7050003 | H38: =H36*H37 -> -49.5865 | I38: =I36*I37 -> 8.1243329 | J38: =J36*J37 -> 3.6683734 | ... M38: =M36*M37 -> 1.4351649
A40: SUSTAINABLE GROWTH
A41: Payout ratio | B41: ='Fin-Forecast'!B36*'Fin-Forecast'!B34/'Fin-Forecast'!B32 -> 0.80575514 | C41: ='Fin-Forecast'!C36*'Fin-Forecast'!C34/'Fin-Forecast'!C32 -> 0.85112205 | D41: ='Fin-Forecast'!D36*'Fin-Forecast'!D34/'Fin-Forecast'!D32 -> 2.1776266 | E41: ='Fin-Forecast'!E36*'Fin-Forecast'!E34/'Fin-Forecast'!E32 -> 2.63147 | F41: ='Fin-Forecast'!F36*'Fin-Forecast'!F34/'Fin-Forecast'!F32 -> 2.8166388 | G41: ='Fin-Forecast'!G36*'Fin-Forecast'!G34/'Fin-Forecast'!G32 -> 0.76977069 | H41: ='Fin-Forecast'!H36*'Fin-Forecast'!H34/'Fin-Forecast'!H32 -> 0.74827425 | I41: ='Fin-Forecast'!I36*'Fin-Forecast'!I34/'Fin-Forecast'!I32 -> 0.73723595 | ... M41: ='Fin-Forecast'!M36*'Fin-Forecast'!M34/'Fin-Forecast'!M32 -> 0.75891259
A42: Retention ratio | B42: =1-B41 -> 0.19424486 | C42: =1-C41 -> 0.14887795 | D42: =1-D41 -> -1.1776266 | E42: =1-E41 -> -1.63147 | F42: =1-F41 -> -1.8166388 | G42: =1-G41 -> 0.23022931 | H42: =1-H41 -> 0.25172575 | I42: =1-I41 -> 0.26276405 | ... M42: =1-M41 -> 0.24108741
A43: Sustainable growth rate | C43: =C38*C42 -> 0.107408 | D43: =D38*D42 -> -0.41110741 | E43: =E38*E42 -> -1.0104742 | F43: =F38*F42 -> -276.52545 | G43: =G38*G42 -> -1.5436876 | H43: =H38*H42 -> -12.482199 | I43: =I38*I42 -> 2.1347826 | J43: =J38*J42 -> 0.97847078 | ... M43: =M38*M42 -> 0.34600017

Sheet Fin-FCF
A1: Free Cash Flow — ABBV
A2: FCFF and FCFE, ex cash/debt and with cash/debt. Actuals + Base case. $mm.
A4: ($ in millions) | B4: 2021A | C4: 2022A | D4: 2023A | E4: 2024A | F4: 2025A | G4: 2026E | H4: 2027E | I4: 2028E | J4: 2029E | K4: 2030E | L4: 2031E | M4: 2032E
A5: WITHOUT CASH AND DEBT
A6: NOPAT | B6: ='Fin-Forecast'!B33 -> 16786.65 | C6: ='Fin-Forecast'!C33 -> 19211.7 | D6: ='Fin-Forecast'!D33 -> 15369.7 | E6: ='Fin-Forecast'!E33 -> 14131.25 | F6: ='Fin-Forecast'!F33 -> 17776.05 | G6: ='Fin-Forecast'!G33 -> 18735.754 | H6: ='Fin-Forecast'!H33 -> 19961.844 | I6: ='Fin-Forecast'!I33 -> 21041.52 | ... M6: ='Fin-Forecast'!M33 -> 24166.516
A7: NWC ex cash (EOY) | B7: ='Fin-Capital'!B11 -> 4859.2555 | C7: ='Fin-Capital'!C11 -> 6054.7904 | D7: ='Fin-Capital'!D11 -> 6515.763 | E7: ='Fin-Capital'!E11 -> 6759.1822 | F7: ='Fin-Capital'!F11 -> 8188.8493 | G7: ='Fin-Capital'!G11 -> 8298.1888 | H7: ='Fin-Capital'!H11 -> 8713.0982 | I7: ='Fin-Capital'!I11 -> 9105.1877 | ... M7: ='Fin-Capital'!M11 -> 10397.694
A8: NFA (EOY) | B8: ='Fin-Capital'!B12 -> 124066.25 | C8: ='Fin-Capital'!C12 -> 115585.46 | D8: ='Fin-Capital'!D12 -> 106901.99 | E8: ='Fin-Capital'!E12 -> 114343.43 | F8: ='Fin-Capital'!F12 -> 112418.7 | G8: ='Fin-Capital'!G12 -> 120054.81 | H8: ='Fin-Capital'!H12 -> 126057.56 | I8: ='Fin-Capital'!I12 -> 131730.15 | ... M8: ='Fin-Capital'!M12 -> 150429.6
A9: - Change in NWC | C9: =C7-B7 -> 1195.5349 | D9: =D7-C7 -> 460.9726 | E9: =E7-D7 -> 243.41918 | F9: =F7-E7 -> 1429.6671 | G9: =G7-F7 -> 109.33948 | H9: =H7-G7 -> 414.90944 | I9: =I7-H7 -> 392.08942 | J9: =J7-I7 -> 364.20751 | ... M9: =M7-L7 -> 302.84546
A10: - Change in NFA | C10: =C8-B8 -> -8480.7945 | D10: =D8-C8 -> -8683.4712 | E10: =E8-D8 -> 7441.4438 | F10: =F8-E8 -> -1924.7315 | G10: =G8-F8 -> 7636.1162 | H10: =H8-G8 -> 6002.7407 | I10: =I8-H8 -> 5672.59 | J10: =J8-I8 -> 5269.2058 | ... M10: =M8-L8 -> 4381.4448
A11: FCFF (ex cash/debt) | C11: =C6-C9-C10 -> 26496.96 | D11: =D6-D9-D10 -> 23592.199 | E11: =E6-E9-E10 -> 6446.387 | F11: =F6-F9-F10 -> 18271.114 | G11: =G6-G9-G10 -> 10990.299 | H11: =H6-H9-H10 -> 13544.194 | I11: =I6-I9-I10 -> 14976.84 | J11: =J6-J9-J10 -> 16375.532 | ... M11: =M6-M9-M10 -> 19482.226
A12: FCFF/share | C12: =C11/'Fin-Forecast'!C34 -> 14.902677 | D12: =D11/'Fin-Forecast'!D34 -> 13.306373 | E12: =E11/'Fin-Forecast'!E34 -> 3.6358641 | F12: =F11/'Fin-Forecast'!F34 -> 10.305197 | G12: =G11/'Fin-Forecast'!G34 -> 6.2292533 | H12: =H11/'Fin-Forecast'!H34 -> 7.7124749 | I12: =I11/'Fin-Forecast'!I34 -> 8.5657872 | J12: =J11/'Fin-Forecast'!J34 -> 9.4048689 | ... M12: =M11/'Fin-Forecast'!M34 -> 11.317189
A13: - After-tax interest | B13: ='Fin-Forecast'!B29*(1-0.15) -> 2081.65 | C13: ='Fin-Forecast'!C29*(1-0.15) -> 1994.1 | D13: ='Fin-Forecast'!D29*(1-0.15) -> 2006 | E13: ='Fin-Forecast'!E29*(1-0.15) -> 2510.9 | F13: ='Fin-Forecast'!F29*(1-0.15) -> 2600.15 | G13: ='Fin-Forecast'!G29*(1-0.15) -> 2577.2467 | H13: ='Fin-Forecast'!H29*(1-0.15) -> 2500.7467 | I13: ='Fin-Forecast'!I29*(1-0.15) -> 2424.2467 | ... M13: ='Fin-Forecast'!M29*(1-0.15) -> 2118.2467
A14: FCFE (ex cash/debt) | C14: =C11-C13 -> 24502.86 | D14: =D11-D13 -> 21586.199 | E14: =E11-E13 -> 3935.487 | F14: =F11-F13 -> 15670.964 | G14: =G11-G13 -> 8413.052 | H14: =H11-H13 -> 11043.447 | I14: =I11-I13 -> 12552.593 | J14: =J11-J13 -> 14027.786 | ... M14: =M11-M13 -> 17363.979
A16: WITH CASH AND DEBT
A17: NOPAT | B17: ='Fin-Forecast'!B33 -> 16786.65 | C17: ='Fin-Forecast'!C33 -> 19211.7 | D17: ='Fin-Forecast'!D33 -> 15369.7 | E17: ='Fin-Forecast'!E33 -> 14131.25 | F17: ='Fin-Forecast'!F33 -> 17776.05 | G17: ='Fin-Forecast'!G33 -> 18735.754 | H17: ='Fin-Forecast'!H33 -> 19961.844 | I17: ='Fin-Forecast'!I33 -> 21041.52 | ... M17: ='Fin-Forecast'!M33 -> 24166.516
A18: NOWC (EOY) | B18: ='Fin-Capital'!B10 -> 14689.255 | C18: ='Fin-Capital'!C10 -> 15283.79 | D18: ='Fin-Capital'!D10 -> 19331.763 | E18: ='Fin-Capital'!E10 -> 12314.182 | F18: ='Fin-Capital'!F10 -> 13445.849 | G18: ='Fin-Capital'!G10 -> 13555.189 | H18: ='Fin-Capital'!H10 -> 13970.098 | I18: ='Fin-Capital'!I10 -> 14362.188 | ... M18: ='Fin-Capital'!M10 -> 15654.694
A19: NFA (EOY) | B19: ='Fin-Capital'!B12 -> 124066.25 | C19: ='Fin-Capital'!C12 -> 115585.46 | D19: ='Fin-Capital'!D12 -> 106901.99 | E19: ='Fin-Capital'!E12 -> 114343.43 | F19: ='Fin-Capital'!F12 -> 112418.7 | G19: ='Fin-Capital'!G12 -> 120054.81 | H19: ='Fin-Capital'!H12 -> 126057.56 | I19: ='Fin-Capital'!I12 -> 131730.15 | ... M19: ='Fin-Capital'!M12 -> 150429.6
A20: - Change in NOWC | C20: =C18-B18 -> 594.53493 | D20: =D18-C18 -> 4047.9726 | E20: =E18-D18 -> -7017.5808 | F20: =F18-E18 -> 1131.6671 | G20: =G18-F18 -> 109.33948 | H20: =H18-G18 -> 414.90944 | I20: =I18-H18 -> 392.08942 | J20: =J18-I18 -> 364.20751 | ... M20: =M18-L18 -> 302.84546
A21: - Change in NFA | C21: =C19-B19 -> -8480.7945 | D21: =D19-C19 -> -8683.4712 | E21: =E19-D19 -> 7441.4438 | F21: =F19-E19 -> -1924.7315 | G21: =G19-F19 -> 7636.1162 | H21: =H19-G19 -> 6002.7407 | I21: =I19-H19 -> 5672.59 | J21: =J19-I19 -> 5269.2058 | ... M21: =M19-L19 -> 4381.4448
A22: FCFF (with cash/debt) | C22: =C17-C20-C21 -> 27097.96 | D22: =D17-D20-D21 -> 20005.199 | E22: =E17-E20-E21 -> 13707.387 | F22: =F17-F20-F21 -> 18569.114 | G22: =G17-G20-G21 -> 10990.299 | H22: =H17-H20-H21 -> 13544.194 | I22: =I17-I20-I21 -> 14976.84 | J22: =J17-J20-J21 -> 16375.532 | ... M22: =M17-M20-M21 -> 19482.226
A23: - After-tax interest | B23: ='Fin-Forecast'!B29*(1-0.15) -> 2081.65 | C23: ='Fin-Forecast'!C29*(1-0.15) -> 1994.1 | D23: ='Fin-Forecast'!D29*(1-0.15) -> 2006 | E23: ='Fin-Forecast'!E29*(1-0.15) -> 2510.9 | F23: ='Fin-Forecast'!F29*(1-0.15) -> 2600.15 | G23: ='Fin-Forecast'!G29*(1-0.15) -> 2577.2467 | H23: ='Fin-Forecast'!H29*(1-0.15) -> 2500.7467 | I23: ='Fin-Forecast'!I29*(1-0.15) -> 2424.2467 | ... M23: ='Fin-Forecast'!M29*(1-0.15) -> 2118.2467
A24: + Net new debt | C24: ='Fin-Capital'!C18-'Fin-Capital'!B18 -> -13384 | D24: ='Fin-Capital'!D18-'Fin-Capital'!C18 -> -4071 | E24: ='Fin-Capital'!E18-'Fin-Capital'!D18 -> 7721 | F24: ='Fin-Capital'!F18-'Fin-Capital'!E18 -> 538 | G24: ='Fin-Capital'!G18-'Fin-Capital'!F18 -> -2000 | H24: ='Fin-Capital'!H18-'Fin-Capital'!G18 -> -2000 | I24: ='Fin-Capital'!I18-'Fin-Capital'!H18 -> -2000 | J24: ='Fin-Capital'!J18-'Fin-Capital'!I18 -> -2000 | ... M24: ='Fin-Capital'!M18-'Fin-Capital'!L18 -> -2000
A25: FCFE (with cash/debt) | C25: =C22-C23+C24 -> 11719.86 | D25: =D22-D23+D24 -> 13928.199 | E25: =E22-E23+E24 -> 18917.487 | F25: =F22-F23+F24 -> 16506.964 | G25: =G22-G23+G24 -> 6413.052 | H25: =H22-H23+H24 -> 9043.4473 | I25: =I22-I23+I24 -> 10552.593 | J25: =J22-J23+J24 -> 12027.786 | ... M25: =M22-M23+M24 -> 15363.979

Sheet Charts
A1: AbbVie — Market Profile & Historical Data
A3: MARKET PROFILE
A4: Closing price | B4: $224.77
A5: Shares outstanding (M) | B5: 1,773
A6: Market cap ($B) | B6: ~$398B
A7: Enterprise value ($B) | B7: ~$461B
A8: EV/EBITDA (NTM) | B8: ~16x
A9: Dividend yield | B9: ~3.0%
A10: WACC | B10: 7.6%
A13: HISTORICAL SALES, EBIT, ROIC
A14: Year | B14: Sales | C14: EBIT | D14: EBIT %
A15: 2021 | B15: 56197 | C15: 19749 | D15: =C15/B15 -> 0.35142445
A16: 2022 | B16: 58054 | C16: 22602 | D16: =C16/B16 -> 0.38932718
A17: 2023 | B17: 54318 | C17: 18082 | D17: =C17/B17 -> 0.33289149
A18: 2024 | B18: 56334 | C18: 16625 | D18: =C18/B18 -> 0.29511485
A19: 2025 | B19: 61160 | C19: 20913 | D19: =C19/B19 -> 0.34193918

Sheet DCF-FCFF
A1: DCF — Firm (FCFF)
A2: FCFF discounted at WACC. 7 explicit years + terminal value (EV/EBIT and constant growth). $mm.
A4: INPUTS ($mm)
A5: WACC | B5: =Drivers!D25 -> 0.075736
A6: g | B6: =Drivers!D36 -> 0.03
A7: P/E | B7: =Drivers!D37 -> 13
A8: Market Cap | B8: =Drivers!D10 -> 63122
A9: Diluted shares | B9: =Drivers!D9 -> 1773
A10: Current Share Price | B10: =Drivers!D8 -> 224.77
A12: EXPLICIT FORECAST
A13: Year | C13: 2026E | D13: 2027E | E13: 2028E | F13: 2029E | G13: 2030E | H13: 2031E | I13: 2032E
A14: Period (t) | C14: 1 | D14: 2 | E14: 3 | F14: 4 | G14: 5 | H14: 6 | I14: 7
A15: FCFF (base, with cash/debt) | C15: ='Fin-FCF'!G22 -> 10990.299 | D15: ='Fin-FCF'!H22 -> 13544.194 | E15: ='Fin-FCF'!I22 -> 14976.84 | F15: ='Fin-FCF'!J22 -> 16375.532 | G15: ='Fin-FCF'!K22 -> 17652.853 | H15: ='Fin-FCF'!L22 -> 18914.782 | I15: ='Fin-FCF'!M22 -> 19482.226
A16: Discount factor @ WACC | C16: =1/(1+$B$5)^1 -> 0.92959611 | D16: =1/(1+$B$5)^2 -> 0.86414893 | E16: =1/(1+$B$5)^3 -> 0.80330948 | F16: =1/(1+$B$5)^4 -> 0.74675337 | G16: =1/(1+$B$5)^5 -> 0.69417902 | H16: =1/(1+$B$5)^6 -> 0.64530612 | I16: =1/(1+$B$5)^7 -> 0.59987406
A17: PV of FCFF | C17: =C15*C16 -> 10216.539 | D17: =D15*D16 -> 11704.201 | E17: =E15*E16 -> 12031.038 | F17: =F15*F16 -> 12228.484 | G17: =G15*G16 -> 12254.24 | H17: =H15*H16 -> 12205.825 | I17: =I15*I16 -> 11686.882
A19: VALUATION
A20: Sum PV explicit FCFF | B20: =SUM(C17:I17) -> 82327.208
A21: Terminal EBIT (yr7) | B21: ='Fin-Forecast'!M25 -> 28431.195
A22: Terminal value (EV/EBIT) | B22: =B21*B7 -> 369605.54
A23: PV terminal (EV/EBIT) | B23: =B22*I16 -> 221716.77
A24: Terminal FCFF (yr7×(1+g)) | B24: =I15*(1+B6) -> 20066.692
A25: Terminal value (const growth) | B25: =B24/(B5-B6) -> 438750.49
A26: PV terminal (const growth) | B26: =B25*I16 -> 263195.04
A28: Enterprise value (blend) | B28: =B20+(B23+B26)/2 -> 324783.11
A29: - Net debt | B29: =-B8 -> -63122
A30: Equity value | B30: =B28-B8 -> 261661.11
A31: Value per share | B31: =B30/B9 -> 147.581
A32: Upside / (downside) | B32: =B31/B10-1 -> -0.34341327

Sheet DCF-FCFE
A1: DCF — Equity (FCFE)
A2: FCFE discounted at cost of equity. Terminal value via P/E and constant growth. $mm.
A4: INPUTS ($mm)
A5: CAPM | B5: =Drivers!D19 -> 0.0805
A6: g | B6: =Drivers!D36 -> 0.03
A7: P/E | B7: =Drivers!D38 -> 12
A8: Diluted shares | B8: =Drivers!D9 -> 1773
A9: Current Share Price | B9: =Drivers!D8 -> 224.77
A11: EXPLICIT FORECAST
A12: Year | C12: 2026E | D12: 2027E | E12: 2028E | F12: 2029E | G12: 2030E | H12: 2031E | I12: 2032E
A13: Period (t) | C13: 1 | D13: 2 | E13: 3 | F13: 4 | G13: 5 | H13: 6 | I13: 7
A14: FCFE (with cash/debt) | C14: ='Fin-FCF'!G25 -> 6413.052 | D14: ='Fin-FCF'!H25 -> 9043.4473 | E14: ='Fin-FCF'!I25 -> 10552.593 | F14: ='Fin-FCF'!J25 -> 12027.786 | G14: ='Fin-FCF'!K25 -> 13381.606 | H14: ='Fin-FCF'!L25 -> 14720.035 | I14: ='Fin-FCF'!M25 -> 15363.979
A15: Discount factor @ Ke | C15: =1/(1+$B$5)^1 -> 0.92549745 | D15: =1/(1+$B$5)^2 -> 0.85654554 | E15: =1/(1+$B$5)^3 -> 0.79273072 | F15: =1/(1+$B$5)^4 -> 0.73367026 | G15: =1/(1+$B$5)^5 -> 0.67900996 | H15: =1/(1+$B$5)^6 -> 0.62842199 | I15: =1/(1+$B$5)^7 -> 0.58160295
A16: PV of FCFE | C16: =C14*C15 -> 5935.2633 | D16: =D14*D15 -> 7746.1244 | E16: =E14*E15 -> 8365.365 | F16: =F14*F15 -> 8824.4287 | G16: =G14*G15 -> 9086.2438 | H16: =H14*H15 -> 9250.3939 | I16: =I14*I15 -> 8935.7354
A18: VALUATION
A19: Sum PV explicit FCFE | B19: =SUM(C16:I16) -> 58143.554
A20: Terminal net income (yr7) | B20: ='Fin-Forecast'!M32 -> 22048.269
A21: Terminal value (P/E) | B21: =B20*B7 -> 264579.23
A22: PV terminal (P/E) | B22: =B21*I15 -> 153880.06
A23: Terminal FCFE (yr7×(1+g)) | B23: =I14*(1+B6) -> 15824.898
A24: Terminal value (const growth) | B24: =B23/(B5-B6) -> 313364.32
A25: PV terminal (const growth) | B25: =B24*I15 -> 182253.61
A27: Equity value (blend) | B27: =B19+(B22+B25)/2 -> 226210.39
A28: Value per share | B28: =B27/B8 -> 127.58623
A29: Upside / (downside) | B29: =B28/B9-1 -> -0.43236983

Sheet EVA-Residual
A1: EVA & Residual Income
A2: EVA = NOPAT - WACC×IC. Residual Income = NI - Ke×BV. $mm.
A4: INPUTS ($mm)
A5: WACC | B5: =Drivers!D25 -> 0.075736
A6: CAPM | B6: =Drivers!D19 -> 0.0805
A7: g | B7: =Drivers!D36 -> 0.03
A8: Invested capital (ex cash) | B8: ='Fin-Capital'!F13 -> 120607.55
A9: Equity | B9: ='Fin-Capital'!F20 -> -3270
A10: Market Cap | B10: =Drivers!D10 -> 63122
A11: Diluted shares | B11: =Drivers!D9 -> 1773
A12: Current Share Price | B12: =Drivers!D8 -> 224.77
A14: EVA (firm)
A15: Year | C15: 2026E | D15: 2027E | E15: 2028E | F15: 2029E | G15: 2030E | H15: 2031E | I15: 2032E
A16: NOPAT | C16: ='Fin-Forecast'!G33 -> 18735.754 | D16: ='Fin-Forecast'!H33 -> 19961.844 | E16: ='Fin-Forecast'!I33 -> 21041.52 | F16: ='Fin-Forecast'!J33 -> 22008.946 | G16: ='Fin-Forecast'!K33 -> 22779.259 | H16: ='Fin-Forecast'!L33 -> 23462.637 | I16: ='Fin-Forecast'!M33 -> 24166.516
A17: Beginning IC | C17: ='Fin-Capital'!F13 -> 120607.55 | D17: ='Fin-Capital'!G13 -> 128353 | E17: ='Fin-Capital'!H13 -> 134770.65 | F17: ='Fin-Capital'!I13 -> 140835.33 | G17: ='Fin-Capital'!J13 -> 146468.75 | H17: ='Fin-Capital'!K13 -> 151595.15 | I17: ='Fin-Capital'!L13 -> 156143.01
A18: Capital charge (WACC×IC) | C18: =$B$5*C17 -> 9134.3333 | D18: =$B$5*D17 -> 9720.9431 | E18: =$B$5*E17 -> 10206.99 | F18: =$B$5*F17 -> 10666.305 | G18: =$B$5*G17 -> 11092.957 | H18: =$B$5*H17 -> 11481.21 | I18: =$B$5*I17 -> 11825.647
A19: EVA | C19: =C16-C18 -> 9601.4211 | D19: =D16-D18 -> 10240.901 | E19: =E16-E18 -> 10834.529 | F19: =F16-F18 -> 11342.641 | G19: =G16-G18 -> 11686.302 | H19: =H16-H18 -> 11981.426 | I19: =I16-I18 -> 12340.869
A20: Discount factor | C20: =1/(1+$B$5)^1 -> 0.92959611 | D20: =1/(1+$B$5)^2 -> 0.86414893 | E20: =1/(1+$B$5)^3 -> 0.80330948 | F20: =1/(1+$B$5)^4 -> 0.74675337 | G20: =1/(1+$B$5)^5 -> 0.69417902 | H20: =1/(1+$B$5)^6 -> 0.64530612 | I20: =1/(1+$B$5)^7 -> 0.59987406
A21: PV of EVA | C21: =C19*C20 -> 8925.4437 | D21: =D19*D20 -> 8849.6637 | E21: =E19*E20 -> 8703.4801 | F21: =F19*F20 -> 8470.1554 | G21: =G19*G20 -> 8112.3857 | H21: =H19*H20 -> 7731.6876 | I21: =I19*I20 -> 7402.9671
A23: Sum PV EVA | B23: =SUM(C21:I21) -> 58195.783
A24: Terminal EVA | B24: =I19*(1+B7) -> 12711.095
A25: PV terminal EVA | B25: =B24/(B5-B7)*I20 -> 166718.91
A26: MVA = ΣPV + PV term | B26: =B23+B25 -> 224914.7
A27: Enterprise value = IC0 + MVA | B27: =B8+B26 -> 345522.24
A28: Equity value | B28: =B27-B10 -> 282400.24
A29: Value per share (EVA) | B29: =B28/B11 -> 159.2782
A31: RESIDUAL INCOME (equity)
A32: Year | C32: 2026E | D32: 2027E | E32: 2028E | F32: 2029E | G32: 2030E | H32: 2031E | I32: 2032E
A33: Net income | C33: ='Fin-Forecast'!G32 -> 16158.508 | D33: ='Fin-Forecast'!H32 -> 17461.097 | E33: ='Fin-Forecast'!I32 -> 18617.273 | F33: ='Fin-Forecast'!J32 -> 19661.199 | G33: ='Fin-Forecast'!K32 -> 20508.012 | H33: ='Fin-Forecast'!L32 -> 21267.89 | I33: ='Fin-Forecast'!M32 -> 22048.269
A34: Beginning book value | C34: ='Fin-Capital'!F20 -> -3270 | D34: ='Fin-Capital'!G20 -> -1549.838 | E34: ='Fin-Capital'!H20 -> 845.5698 | F34: ='Fin-Capital'!I20 -> 3737.5198 | G34: ='Fin-Capital'!J20 -> 6981.7812 | H34: ='Fin-Capital'!K20 -> 10349.533 | I34: ='Fin-Capital'!L20 -> 13705.103
A35: Equity charge (Ke×BV) | C35: =$B$6*C34 -> -263.235 | D35: =$B$6*D34 -> -124.76196 | E35: =$B$6*E34 -> 68.068369 | F35: =$B$6*F34 -> 300.87034 | G35: =$B$6*G34 -> 562.03338 | H35: =$B$6*H34 -> 833.13743 | I35: =$B$6*I34 -> 1103.2608
A36: Residual income | C36: =C33-C35 -> 16421.743 | D36: =D33-D35 -> 17585.859 | E36: =E33-E35 -> 18549.204 | F36: =F33-F35 -> 19360.329 | G36: =G33-G35 -> 19945.979 | H36: =H33-H35 -> 20434.752 | I36: =I33-I35 -> 20945.008
A37: Discount factor @ Ke | C37: =1/(1+$B$6)^1 -> 0.92549745 | D37: =1/(1+$B$6)^2 -> 0.85654554 | E37: =1/(1+$B$6)^3 -> 0.79273072 | F37: =1/(1+$B$6)^4 -> 0.73367026 | G37: =1/(1+$B$6)^5 -> 0.67900996 | H37: =1/(1+$B$6)^6 -> 0.62842199 | I37: =1/(1+$B$6)^7 -> 0.58160295
A38: PV of RI | C38: =C36*C37 -> 15198.281 | D38: =D36*D37 -> 15063.089 | E38: =E36*E37 -> 14704.524 | F38: =F36*F37 -> 14204.097 | G38: =G36*G37 -> 13543.518 | H38: =H36*H37 -> 12841.648 | I38: =I36*I37 -> 12181.679
A40: Sum PV RI | B40: =SUM(C38:I38) -> 97736.837
A41: Terminal RI | B41: =I36*(1+B7) -> 21573.359
A42: PV terminal RI | B42: =B41/(B6-B7)*I37 -> 248458
A43: Equity value = BV0 + ΣPV + term | B43: =B9+B40+B42 -> 342924.84
A44: Value per share (RI) | B44: =B43/B11 -> 193.41502

Sheet MVA
A1: Market Value Added (MVA)
A2: Operating + non-operating value vs book. Sources and claims on value. $mm.
A4: SOURCES OF VALUE
A5: Operating value (DCF-FCFF EV) | B5: ='DCF-FCFF'!B28 -> 324783.11
A6: Non-operating (cash + mkt sec) | B6: ='Fin-Capital'!F6 -> 5257
A7: Total firm value | B7: =B5+B6 -> 330040.11
A9: CLAIMS ON VALUE
A10: Debt (book) | B10: ='Fin-Capital'!F18 -> 68379
A11: Other liabilities (book) | B11: ='Fin-Capital'!F19 -> 57655.548
A12: Intrinsic equity value | B12: =B7-B10-B11 -> 204005.56
A14: MARKET VS BOOK
A15: Intrinsic equity value | B15: =B12 -> 204005.56
A16: Book equity value | B16: ='Fin-Capital'!F20 -> -3270
A17: Market value added | B17: =B12-B16 -> 207275.56
A18: Intrinsic value per share | B18: =B12/Drivers!D9 -> 115.06236

Sheet Comps
A1: Trading Comparables
A2: Peer multiples applied to ABBV NTM (2026E). $mm except per share.
A4: ABBV SNAPSHOT
A5: Enterprise value | B5: =Drivers!D12 -> 461639.21
A6: NTM EBITDA (2026E) | B6: ='Fin-Forecast'!G25*1.39 -> 30638.469
A7: NTM EPS (2026E) | B7: ='Fin-Forecast'!G35 -> 9.1585716
A9: IMPLIED VALUE FROM PEERS
A10: Method | B10: Multiple | C10: Per share | D10: Upside
A11: EV/EBITDA low | B11: =Drivers!D48 -> 11 | C11: =(B6*B11-Drivers!D10)/Drivers!D9 -> 154.48458 | D11: =C11/Drivers!D8-1 -> -0.3126993
A12: EV/EBITDA high | B12: =Drivers!D49 -> 16 | C12: =(B6*B12-Drivers!D10)/Drivers!D9 -> 240.88748 | D12: =C12/Drivers!D8-1 -> 0.071706548
